<?xml version='1.0' ?>
<sdf version='1.6'>
  <world name='simslides'>

    <gui>

      <plugin filename="GzScene3D" name="3D View">
        <ignition-gui>
          <title>3D View</title>
          <property type="bool" key="showTitleBar">false</property>
          <property type="string" key="state">docked</property>
        </ignition-gui>

        <engine>ogre2</engine>
        <scene>scene</scene>
        <ambient_light>0.3 0.3 0.3</ambient_light>
        <background_color>0.8 0.8 0.8</background_color>
        <camera_pose>-4.85 -14.95 2.99 0 0.2 2.45</camera_pose>
      </plugin>

      <plugin filename="WorldControl" name="World control">
        <ignition-gui>
          <title>World control</title>
          <property type="bool" key="showTitleBar">false</property>
          <property type="bool" key="resizable">false</property>
          <property type="double" key="height">72</property>
          <property type="double" key="width">121</property>
          <property type="double" key="z">1</property>

          <property type="string" key="state">floating</property>
          <anchors target="3D View">
            <line own="left" target="left"/>
            <line own="bottom" target="bottom"/>
          </anchors>
        </ignition-gui>

        <play_pause>true</play_pause>
        <step>true</step>
        <start_paused>true</start_paused>

      </plugin>

      <plugin filename="WorldStats" name="World stats">
        <ignition-gui>
          <title>World stats</title>
          <property type="bool" key="showTitleBar">false</property>
          <property type="bool" key="resizable">false</property>
          <property type="double" key="height">110</property>
          <property type="double" key="width">290</property>
          <property type="double" key="z">1</property>

          <property type="string" key="state">floating</property>
          <anchors target="3D View">
            <line own="right" target="right"/>
            <line own="bottom" target="bottom"/>
          </anchors>
        </ignition-gui>

        <sim_time>true</sim_time>
        <real_time>true</real_time>
        <real_time_factor>true</real_time_factor>
        <iterations>true</iterations>

      </plugin>

      <plugin filename="KeyPublisher" name="Key publisher">
        <ignition-gui>
          <anchors target="3D View">
            <line own="right" target="right"/>
            <line own="top" target="top"/>
          </anchors>
          <property key="resizable" type="bool">false</property>
          <property key="width" type="double">5</property>
          <property key="height" type="double">5</property>
          <property key="state" type="string">floating</property>
          <property key="showTitleBar" type="bool">false</property>
        </ignition-gui>
      </plugin>

      <plugin filename="TransformControl" name="Transform control">
        <ignition-gui>
          <title>Transform control</title>
          <property key="x" type="double">200</property>
          <property key="resizable" type="bool">false</property>
          <property key="width" type="double">250</property>
          <property key="height" type="double">50</property>
          <property key="state" type="string">floating</property>
          <property key="showTitleBar" type="bool">false</property>
          <property key="cardBackground" type="string">#666666</property>
        </ignition-gui>
      </plugin>

      <!-- Insert simple shapes -->
      <plugin filename="Shapes" name="Shapes">
        <ignition-gui>
          <property key="x" type="double">450</property>
          <property key="resizable" type="bool">false</property>
          <property key="width" type="double">150</property>
          <property key="height" type="double">50</property>
          <property key="state" type="string">floating</property>
          <property key="showTitleBar" type="bool">false</property>
          <property key="cardBackground" type="string">#666666</property>
        </ignition-gui>
      </plugin>

      <plugin filename="VisualizeLidar" name="Lidar">
        <ignition-gui>
          <title>Lidar</title>
          <property key="x" type="double">600</property>
          <property key="resizable" type="bool">true</property>
          <property key="showDockButton" type="bool">false</property>
          <property key="showCloseButton" type="bool">false</property>
          <property key="cardBackground" type="string">#44000022</property>
          <property key="width" type="double">100</property>
          <property key="height" type="double">100</property>
          <property key="state" type="string">floating_collapsed</property>
        </ignition-gui>
      </plugin>

      <plugin filename="ImageDisplay" name="Camera">
        <ignition-gui>
          <title>Camera</title>
          <property key="x" type="double">700</property>
          <property key="resizable" type="bool">true</property>
          <property key="showDockButton" type="bool">false</property>
          <property key="showCloseButton" type="bool">false</property>
          <property key="cardBackground" type="string">#44000022</property>
          <property key="width" type="double">130</property>
          <property key="height" type="double">100</property>
          <property key="state" type="string">floating_collapsed</property>
        </ignition-gui>
      </plugin>

      <plugin name="SimSlides" filename="SimSlidesIgn">
        <ignition-gui>
          <title>SimSlides</title>
          <property type="bool" key="showTitleBar">false</property>
          <property type="bool" key="resizable">false</property>
          <property type="double" key="height">50</property>
          <property type="double" key="width">200</property>
          <property type="string" key="cardBackground">#44000022</property>
          <property type="string" key="state">floating</property>
          <anchors target="3D View">
            <line own="left" target="left"/>
            <line own="top" target="top"/>
          </anchors>
        </ignition-gui>

        <near_clip>0.01</near_clip>
        <far_clip>500</far_clip>

        <keyframe type='lookat' visual='slide-0'/>
        <keyframe type='lookat' visual='slide-1'/>
        <keyframe type='lookat' visual='slide-2' eye_offset="0 -3.0 1 0 0 1.57"/>
        <keyframe type='lookat' visual='slide-3'/>
        <keyframe type='stack' visual='slide-4'/>
        <keyframe type='stack' visual='slide-5'/>
        <keyframe type='lookat' visual='slide-6'/>
        <keyframe type='lookat' visual='slide-7'/>
        <keyframe type='lookat' visual='slide-8'/>
        <keyframe type='lookat' visual='slide-9'/>
        <keyframe type='lookat' visual='slide-10'/>
        <keyframe type='lookat' visual='slide-11'/>
        <keyframe type='lookat' visual='slide-12'/>
        <keyframe type='lookat' visual='slide-13'/>
        <keyframe type='lookat' visual='slide-14'/>
        <keyframe type='lookat' visual='slide-15'/>
      </plugin>

    </gui>

    <plugin
      filename="ignition-gazebo-physics-system"
      name="ignition::gazebo::systems::Physics">
    </plugin>
    <plugin
      filename="ignition-gazebo-user-commands-system"
      name="ignition::gazebo::systems::UserCommands">
    </plugin>
    <plugin
      filename="ignition-gazebo-scene-broadcaster-system"
      name="ignition::gazebo::systems::SceneBroadcaster">
    </plugin>
    <plugin
      filename="ignition-gazebo-sensors-system"
      name="ignition::gazebo::systems::Sensors">
     <engine>ogre</engine>
    </plugin>

    <include>
      <uri>
        https://fuel.ignitionrobotics.org/1.0/OpenRobotics/models/Sun
      </uri>
    </include>

    <include>
      <uri>
        https://fuel.ignitionrobotics.org/1.0/OpenRobotics/models/Ground Plane
      </uri>
    </include>

    <include>
      <pose>-13.9 -5.9 0 0 0 -0.73</pose>
      <uri>
        https://fuel.ignitionrobotics.org/1.0/OpenRobotics/models/Double pendulum with base
      </uri>
    </include>

    <include>
      <pose>-10.9 -2.9 0 0 0 -0.73</pose>
      <uri>
        models/Extinguisher PBR
      </uri>
    </include>

    <include>
      <pose>-11.9 -2.9 0 0 0 -0.73</pose>
      <uri>
        https://fuel.ignitionrobotics.org/1.0/OpenRobotics/models/Fire Extinguisher
      </uri>
    </include>

    <model name="vehicle">
        <link name="base_link">
            <inertial>
                <pose>0.002225 0.033355 0.022792 0 -0 0</pose>
                <mass>111.0015</mass>
                <inertia>
                    <ixx>4.49753</ixx>
                    <ixy>0.00199937</ixy>
                    <ixz>-0.00152659</ixz>
                    <iyy>2.46329</iyy>
                    <iyz>-0.424901</iyz>
                    <izz>5.57714</izz>
                </inertia>
            </inertial>
            <collision name="base_link_collision">
                <pose>0.25 0 0.0480 0 0 0</pose>
                <geometry>
                    <box>
                        <size>0.6 0.55 0.428</size>
                    </box>
                </geometry>
            </collision>
            <collision name="base_link_fixed_joint_lump__sensor_payload_link_collision_1">
                <pose>0.38 0 0.4 0 0 0</pose>
                <geometry>
                    <box>
                        <size>0.28 0.28 0.4</size>
                    </box>
                </geometry>
            </collision>
            <visual name="connection_visual">
                <pose>0 0 0 0 1.5707 0</pose>
                <geometry>
                    <cylinder>
                        <length>0.5</length>
                        <radius>0.05</radius>
                    </cylinder>
                </geometry>
            </visual>
            <visual name="base_link_visual">
                <pose>0.180 0 .24 0 0 -1.5707963267948966</pose>
                <geometry>
                    <mesh>
                        <uri>https://fuel.ignitionrobotics.org/1.0/OpenRobotics/models/EXPLORER_R2_SENSOR_CONFIG_2/3/files/meshes/r2.dae</uri>
                        <submesh>
                            <name>BodyFront</name>
                            <center>true</center>
                        </submesh>
                    </mesh>
                </geometry>
                <material>
                    <diffuse>1.0 1.0 1.0</diffuse>
                    <specular>1.0 1.0 1.0</specular>
                    <pbr>
                        <metal>
                            <albedo_map>https://fuel.ignitionrobotics.org/1.0/OpenRobotics/models/EXPLORER_R2_SENSOR_CONFIG_2/3/files/materials/textures/R2_Albedo.png</albedo_map>
                            <metalness_map>https://fuel.ignitionrobotics.org/1.0/OpenRobotics/models/EXPLORER_R2_SENSOR_CONFIG_2/3/files/materials/textures/R2_Metalness.png</metalness_map>
                            <roughness_map>https://fuel.ignitionrobotics.org/1.0/OpenRobotics/models/EXPLORER_R2_SENSOR_CONFIG_2/3/files/materials/textures/R2_Roughness.png</roughness_map>
                        </metal>
                    </pbr>
                </material>
            </visual>
            <light name="right_light_source" type="spot">
                <pose frame="">0.358 -0.133 0.45 3.1415926535897931 1.5707963267948966 -1.5707963267948966</pose>
                <attenuation>
                    <range>50</range>
                    <linear>0</linear>
                    <constant>0.1</constant>
                    <quadratic>0.0025</quadratic>
                </attenuation>
                <diffuse>1.0 1.0 0.63 1</diffuse>
                <specular>1.0 1.0 0.63 1</specular>
                <spot>
                    <inner_angle>1</inner_angle>
                    <outer_angle>1.1</outer_angle>
                    <falloff>1</falloff>
                </spot>
                <direction>0 0 -1</direction>
                <cast_shadows>1</cast_shadows>
            </light>
            <light name="front_light" type="spot">
                <pose frame="">0.49 0 0.45 1.5707963267948966 1.5707963267948966 -1.5707963267948966</pose>
                <attenuation>
                    <range>50</range>
                    <linear>0</linear>
                    <constant>0.1</constant>
                    <quadratic>0.0025</quadratic>
                </attenuation>
                <diffuse>0.8 0.8 0.5 1</diffuse>
                <specular>0.8 0.8 0.5 1</specular>
                <spot>
                    <inner_angle>1</inner_angle>
                    <outer_angle>1.1</outer_angle>
                    <falloff>1</falloff>
                </spot>
                <direction>0 -1 0</direction>
                <cast_shadows>1</cast_shadows>
            </light>
            <light name="left_light_source" type="spot">
                <pose frame="">0.358 0.133 0.45 0 1.5707963267948966 -1.5707963267948966</pose>
                <attenuation>
                    <range>50</range>
                    <linear>0</linear>
                    <constant>0.1</constant>
                    <quadratic>0.0025</quadratic>
                </attenuation>
                <diffuse>1.0 1.0 0.63 1</diffuse>
                <specular>1.0 1.0 0.63 1</specular>
                <spot>
                    <inner_angle>1</inner_angle>
                    <outer_angle>1.1</outer_angle>
                    <falloff>1</falloff>
                </spot>
                <direction>0 0 -1</direction>
                <cast_shadows>1</cast_shadows>
            </light>
            <light name="back_light_source" type="spot">
                <pose frame="">0.26 0 0.46 -1.5707963267948966 1.5707963267948966 -1.5707963267948966</pose>
                <attenuation>
                    <range>50</range>
                    <linear>0</linear>
                    <constant>0.1</constant>
                    <quadratic>0.0025</quadratic>
                </attenuation>
                <diffuse>1.0 1.0 0.63 1</diffuse>
                <specular>1.0 1.0 0.63 1</specular>
                <spot>
                    <inner_angle>1</inner_angle>
                    <outer_angle>1.1</outer_angle>
                    <falloff>1</falloff>
                </spot>
                <direction>0 0 -1</direction>
                <cast_shadows>1</cast_shadows>
            </light>
        <sensor name='gpu_lidar' type='gpu_lidar'>
          <pose>0.43 0 0.55 0 0 0</pose>
          <topic>lidar</topic>
          <update_rate>10</update_rate>
          <lidar>
            <scan>
              <horizontal>
                <samples>16</samples>
                <resolution>1</resolution>
                <min_angle>-0.5</min_angle>
                <max_angle>0.5</max_angle>
              </horizontal>
              <vertical>
                <samples>1</samples>
                <resolution>1</resolution>
                <min_angle>0.0</min_angle>
                <max_angle>0.0</max_angle>
              </vertical>
            </scan>
            <range>
              <min>0.08</min>
              <max>3.0</max>
              <resolution>0.01</resolution>
            </range>
          </lidar>
          <alwaysOn>1</alwaysOn>
          <visualize>true</visualize>
        </sensor>
        <sensor name="camera" type="camera">
          <pose>0.55 0 0.33 0 0 0</pose>
          <camera>
            <horizontal_fov>1.047</horizontal_fov>
            <image>
              <width>320</width>
              <height>240</height>
            </image>
            <clip>
              <near>0.1</near>
              <far>100</far>
            </clip>
          </camera>
          <always_on>1</always_on>
          <update_rate>30</update_rate>
          <visualize>true</visualize>
          <topic>camera</topic>
        </sensor>
        </link>
        <link name="Rear_Rocker_Link">
            <pose>-0.047625 0 -0.0254 1.5707963267948966 0 0</pose>
            <inertial>
                <pose>-0.191018 -0.006403 -0 0 -0 0</pose>
                <mass>42.8393</mass>
                <inertia>
                    <ixx>0.848992</ixx>
                    <ixy>0.00301842</ixy>
                    <ixz>5.21788e-06</ixz>
                    <iyy>1.03049</iyy>
                    <iyz>1.2171e-07</iyz>
                    <izz>0.43679</izz>
                </inertia>
            </inertial>
            <collision name="Rear_Rocker_Link_collision">
                <pose>-0.2 0.072 0 0 0 0</pose>
                <geometry>
                    <box>
                        <size>0.42 0.43 0.56</size>
                    </box>
                </geometry>
            </collision>
            <collision name="Rear_Rocker_Link_platform_collision1">
                <pose>-0.70 0.2855 0 -0.005 0 0</pose>
                <geometry>
                    <box>
                        <size>0.17 0.01 0.5</size>
                    </box>
                </geometry>
            </collision>
            <collision name="Rear_Rocker_Link_platform_collision2">
                <pose>-0.35 0.2855 -0.005 -0.005 0 0</pose>
                <geometry>
                    <box>
                        <size>0.678 0.01 0.69</size>
                    </box>
                </geometry>
            </collision>
            <visual name="BodyRear_visual">
                <pose>-0.428 0.068 0 -1.5707963267948966 -1.5707963267948966 0</pose>
                <geometry>
                    <mesh>
                        <uri>https://fuel.ignitionrobotics.org/1.0/OpenRobotics/models/EXPLORER_R2_SENSOR_CONFIG_2/3/files/meshes/r2.dae</uri>
                        <submesh>
                            <name>BodyRear</name>
                            <center>true</center>
                        </submesh>
                    </mesh>
                </geometry>
                <material>
                    <diffuse>1.0 1.0 1.0</diffuse>
                    <specular>1.0 1.0 1.0</specular>
                    <pbr>
                        <metal>
                            <albedo_map>https://fuel.ignitionrobotics.org/1.0/OpenRobotics/models/EXPLORER_R2_SENSOR_CONFIG_2/3/files/materials/textures/R2_Albedo.png</albedo_map>
                            <metalness_map>https://fuel.ignitionrobotics.org/1.0/OpenRobotics/models/EXPLORER_R2_SENSOR_CONFIG_2/3/files/materials/textures/R2_Metalness.png</metalness_map>
                            <roughness_map>https://fuel.ignitionrobotics.org/1.0/OpenRobotics/models/EXPLORER_R2_SENSOR_CONFIG_2/3/files/materials/textures/R2_Roughness.png</roughness_map>
                        </metal>
                    </pbr>
                </material>
            </visual>
        </link>
        <joint name="Center Pivot" type="revolute">
            <child>Rear_Rocker_Link</child>
            <parent>base_link</parent>
            <axis>
                <xyz>-1 0 0</xyz>
                <limit>
                    <lower>-0.5236</lower>
                    <upper>0.5236</upper>
                </limit>
                <dynamics>
                    <damping>10</damping>
                    <friction>0.1</friction>
                    <spring_reference>0.1</spring_reference>
                    <spring_stiffness>100</spring_stiffness>
                </dynamics>
                <use_parent_model_frame>0</use_parent_model_frame>
            </axis>
        </joint>
        <link name="left_front_wheel_link">
            <pose>0.33421 0.363 -0.091538 -0.013747 -0 -1.5707963267948966</pose>
            <inertial>
                <pose>0.007124 -1.6e-05 4e-06 0 -0 0</pose>
                <mass>11.5398</mass>
                <inertia>
                    <ixx>0.127932</ixx>
                    <ixy>6.41777e-06</ixy>
                    <ixz>2.40271e-06</ixz>
                    <iyy>0.0695645</iyy>
                    <iyz>1.35439e-09</iyz>
                    <izz>0.0695643</izz>
                </inertia>
            </inertial>
            <collision name="left_front_wheel_link_collision">
                <pose>0 0 0 3.1415926535897931 1.5707963267948966 3.1415926535897931</pose>
                <geometry>
                    <cylinder>
                        <length>0.1125</length>
                        <radius>0.31</radius>
                    </cylinder>
                </geometry>
                <surface>
                    <friction>
                        <ode>
                            <mu>0.5</mu>
                            <mu2>1</mu2>
                            <fdir1>0 0 1</fdir1>
                            <slip1>0.0000235</slip1>
                            <slip2>0</slip2>
                            <max_vel>10</max_vel>
                            <min_depth>0.1</min_depth>
                        </ode>
                    </friction>
                    <contact>
                        <ode>
                            <kp>1e+07</kp>
                            <kd>0.0001</kd>
                        </ode>
                    </contact>
                </surface>
            </collision>
            <visual name="left_front_wheel_link_visual">
                <geometry>
                    <mesh>
                        <uri>https://fuel.ignitionrobotics.org/1.0/OpenRobotics/models/EXPLORER_R2_SENSOR_CONFIG_2/3/files/meshes/r2.dae</uri>
                        <submesh>
                            <name>WheelFL</name>
                            <center>true</center>
                        </submesh>
                    </mesh>
                </geometry>
                <material>
                    <diffuse>1.0 1.0 1.0</diffuse>
                    <specular>1.0 1.0 1.0</specular>
                    <pbr>
                        <metal>
                            <albedo_map>https://fuel.ignitionrobotics.org/1.0/OpenRobotics/models/EXPLORER_R2_SENSOR_CONFIG_2/3/files/materials/textures/R2_Albedo.png</albedo_map>
                            <metalness_map>https://fuel.ignitionrobotics.org/1.0/OpenRobotics/models/EXPLORER_R2_SENSOR_CONFIG_2/3/files/materials/textures/R2_Metalness.png</metalness_map>
                            <roughness_map>https://fuel.ignitionrobotics.org/1.0/OpenRobotics/models/EXPLORER_R2_SENSOR_CONFIG_2/3/files/materials/textures/R2_Roughness.png</roughness_map>
                        </metal>
                    </pbr>
                </material>
            </visual>
        </link>
        <joint name="left_front_wheel" type="revolute">
            <child>left_front_wheel_link</child>
            <parent>base_link</parent>
            <axis>
                <xyz>-1 0 0</xyz>
                <limit>
                    <lower>-1e+16</lower>
                    <upper>1e+16</upper>
                </limit>
                <dynamics>
                    <damping>10</damping>
                    <friction>0.1</friction>
                    <spring_reference>0</spring_reference>
                    <spring_stiffness>0</spring_stiffness>
                </dynamics>
                <use_parent_model_frame>0</use_parent_model_frame>
            </axis>
        </joint>
        <link name="left_rear_wheel_link">
            <pose>-0.334625 0.363 -0.083399 -0.014389 0.000148 -1.5707963267948966</pose>
            <inertial>
                <pose>0.007124 -1.6e-05 4e-06 0 -0 0</pose>
                <mass>11.5398</mass>
                <inertia>
                    <ixx>0.127932</ixx>
                    <ixy>6.41777e-06</ixy>
                    <ixz>2.40271e-06</ixz>
                    <iyy>0.0695645</iyy>
                    <iyz>1.35439e-09</iyz>
                    <izz>0.0695643</izz>
                </inertia>
            </inertial>
            <collision name="left_rear_wheel_link_collision">
                <pose>0 0 0 3.1415926535897931 1.5707963267948966 3.1415926535897931</pose>
                <geometry>
                    <cylinder>
                        <length>0.1125</length>
                        <radius>0.31</radius>
                    </cylinder>
                </geometry>
                <surface>
                    <friction>
                        <ode>
                            <mu>0.5</mu>
                            <mu2>1</mu2>
                            <fdir1>0 0 1</fdir1>
                            <slip1>0.0000235</slip1>
                            <slip2>0</slip2>
                            <max_vel>10</max_vel>
                            <min_depth>0.1</min_depth>
                        </ode>
                    </friction>
                    <contact>
                        <ode>
                            <kp>1e+07</kp>
                            <kd>0.0001</kd>
                        </ode>
                    </contact>
                </surface>
            </collision>
            <visual name="left_rear_wheel_link_visual">
                <geometry>
                    <mesh>
                        <uri>https://fuel.ignitionrobotics.org/1.0/OpenRobotics/models/EXPLORER_R2_SENSOR_CONFIG_2/3/files/meshes/r2.dae</uri>
                        <submesh>
                            <name>WheelBL</name>
                            <center>true</center>
                        </submesh>
                    </mesh>
                </geometry>
                <material>
                    <diffuse>1.0 1.0 1.0</diffuse>
                    <specular>1.0 1.0 1.0</specular>
                    <pbr>
                        <metal>
                            <albedo_map>https://fuel.ignitionrobotics.org/1.0/OpenRobotics/models/EXPLORER_R2_SENSOR_CONFIG_2/3/files/materials/textures/R2_Albedo.png</albedo_map>
                            <metalness_map>https://fuel.ignitionrobotics.org/1.0/OpenRobotics/models/EXPLORER_R2_SENSOR_CONFIG_2/3/files/materials/textures/R2_Metalness.png</metalness_map>
                            <roughness_map>https://fuel.ignitionrobotics.org/1.0/OpenRobotics/models/EXPLORER_R2_SENSOR_CONFIG_2/3/files/materials/textures/R2_Roughness.png</roughness_map>
                        </metal>
                    </pbr>
                </material>
            </visual>
        </link>
        <joint name="left_rear_wheel" type="revolute">
            <child>left_rear_wheel_link</child>
            <parent>Rear_Rocker_Link</parent>
            <axis>
                <xyz>-1 0 0</xyz>
                <limit>
                    <lower>-1e+16</lower>
                    <upper>1e+16</upper>
                </limit>
                <dynamics>
                    <damping>10</damping>
                    <friction>0.1</friction>
                    <spring_reference>0</spring_reference>
                    <spring_stiffness>0</spring_stiffness>
                </dynamics>
                <use_parent_model_frame>0</use_parent_model_frame>
            </axis>
        </joint>
        <link name="right_front_wheel_link">
            <pose>0.33421 -0.363 -0.091538 -0.013747 -0 1.5707963267948966</pose>
            <inertial>
                <pose>0.007124 -1.6e-05 4e-06 0 -0 0</pose>
                <mass>11.5398</mass>
                <inertia>
                    <ixx>0.127932</ixx>
                    <ixy>6.41777e-06</ixy>
                    <ixz>2.40271e-06</ixz>
                    <iyy>0.0695645</iyy>
                    <iyz>1.35439e-09</iyz>
                    <izz>0.0695643</izz>
                </inertia>
            </inertial>
            <collision name="right_front_wheel_link_collision">
                <pose>0 0 0 3.1415926535897931 1.5707963267948966 3.1415926535897931</pose>
                <geometry>
                    <cylinder>
                        <length>0.1125</length>
                        <radius>0.31</radius>
                    </cylinder>
                </geometry>
                <surface>
                    <friction>
                        <ode>
                            <mu>0.5</mu>
                            <mu2>1</mu2>
                            <fdir1>0 0 1</fdir1>
                            <slip1>0.0000235</slip1>
                            <slip2>0</slip2>
                            <max_vel>10</max_vel>
                            <min_depth>0.1</min_depth>
                        </ode>
                    </friction>
                    <contact>
                        <ode>
                            <kp>1e+07</kp>
                            <kd>0.0001</kd>
                        </ode>
                    </contact>
                </surface>
            </collision>
            <visual name="right_front_wheel_link_visual">
                <geometry>
                    <mesh>
                        <uri>https://fuel.ignitionrobotics.org/1.0/OpenRobotics/models/EXPLORER_R2_SENSOR_CONFIG_2/3/files/meshes/r2.dae</uri>
                        <submesh>
                            <name>WheelFR</name>
                            <center>true</center>
                        </submesh>
                    </mesh>
                </geometry>
                <material>
                    <diffuse>1.0 1.0 1.0</diffuse>
                    <specular>1.0 1.0 1.0</specular>
                    <pbr>
                        <metal>
                            <albedo_map>https://fuel.ignitionrobotics.org/1.0/OpenRobotics/models/EXPLORER_R2_SENSOR_CONFIG_2/3/files/materials/textures/R2_Albedo.png</albedo_map>
                            <metalness_map>https://fuel.ignitionrobotics.org/1.0/OpenRobotics/models/EXPLORER_R2_SENSOR_CONFIG_2/3/files/materials/textures/R2_Metalness.png</metalness_map>
                            <roughness_map>https://fuel.ignitionrobotics.org/1.0/OpenRobotics/models/EXPLORER_R2_SENSOR_CONFIG_2/3/files/materials/textures/R2_Roughness.png</roughness_map>
                        </metal>
                    </pbr>
                </material>
            </visual>
        </link>
        <joint name="right_front_wheel" type="revolute">
            <child>right_front_wheel_link</child>
            <parent>base_link</parent>
            <axis>
                <xyz>1 0 0</xyz>
                <limit>
                    <lower>-1e+16</lower>
                    <upper>1e+16</upper>
                </limit>
                <dynamics>
                    <damping>10</damping>
                    <friction>0.1</friction>
                    <spring_reference>0</spring_reference>
                    <spring_stiffness>0</spring_stiffness>
                </dynamics>
                <use_parent_model_frame>0</use_parent_model_frame>
            </axis>
        </joint>
        <link name="right_rear_wheel_link">
            <pose>-0.334625 -0.363 -0.083401 -0.014389 -0.000148 1.5707963267948966</pose>
            <inertial>
                <pose>0.007124 -1.6e-05 4e-06 0 -0 0</pose>
                <mass>11.5398</mass>
                <inertia>
                    <ixx>0.127932</ixx>
                    <ixy>6.41777e-06</ixy>
                    <ixz>2.40271e-06</ixz>
                    <iyy>0.0695645</iyy>
                    <iyz>1.35439e-09</iyz>
                    <izz>0.0695643</izz>
                </inertia>
            </inertial>
            <collision name="right_rear_wheel_link_collision">
                <pose>0 0 0 3.1415926535897931 1.5707963267948966 3.1415926535897931</pose>
                <geometry>
                    <cylinder>
                        <length>0.1125</length>
                        <radius>0.31</radius>
                    </cylinder>
                </geometry>
                <surface>
                    <friction>
                        <ode>
                            <mu>0.5</mu>
                            <mu2>1</mu2>
                            <fdir1>0 0 1</fdir1>
                            <slip1>0.0000235</slip1>
                            <slip2>0</slip2>
                            <max_vel>10</max_vel>
                            <min_depth>0.1</min_depth>
                        </ode>
                    </friction>
                    <contact>
                        <ode>
                            <kp>1e+07</kp>
                            <kd>0.0001</kd>
                        </ode>
                    </contact>
                </surface>
            </collision>
            <visual name="right_rear_wheel_link_visual">
                <geometry>
                    <mesh>
                        <uri>https://fuel.ignitionrobotics.org/1.0/OpenRobotics/models/EXPLORER_R2_SENSOR_CONFIG_2/3/files/meshes/r2.dae</uri>
                        <submesh>
                            <name>WheelBR</name>
                            <center>true</center>
                        </submesh>
                    </mesh>
                </geometry>
                <material>
                    <diffuse>1.0 1.0 1.0</diffuse>
                    <specular>1.0 1.0 1.0</specular>
                    <pbr>
                        <metal>
                            <albedo_map>https://fuel.ignitionrobotics.org/1.0/OpenRobotics/models/EXPLORER_R2_SENSOR_CONFIG_2/3/files/materials/textures/R2_Albedo.png</albedo_map>
                            <metalness_map>https://fuel.ignitionrobotics.org/1.0/OpenRobotics/models/EXPLORER_R2_SENSOR_CONFIG_2/3/files/materials/textures/R2_Metalness.png</metalness_map>
                            <roughness_map>https://fuel.ignitionrobotics.org/1.0/OpenRobotics/models/EXPLORER_R2_SENSOR_CONFIG_2/3/files/materials/textures/R2_Roughness.png</roughness_map>
                        </metal>
                    </pbr>
                </material>
            </visual>
        </link>
        <joint name="right_rear_wheel" type="revolute">
            <child>right_rear_wheel_link</child>
            <parent>Rear_Rocker_Link</parent>
            <axis>
                <xyz>1 0 0</xyz>
                <limit>
                    <lower>-1e+16</lower>
                    <upper>1e+16</upper>
                </limit>
                <dynamics>
                    <damping>10</damping>
                    <friction>0.1</friction>
                    <spring_reference>0</spring_reference>
                    <spring_stiffness>0</spring_stiffness>
                </dynamics>
                <use_parent_model_frame>0</use_parent_model_frame>
            </axis>
        </joint>

      <pose>-10 -10 0.38 0 0 0.0</pose>
      <plugin
        filename="ignition-gazebo-velocity-control-system"
        name="ignition::gazebo::systems::VelocityControl">
        <topic>cmd_vel</topic>
      </plugin>

      <!-- Moving Forward: W -->
      <plugin filename="libignition-gazebo-triggered-publisher-system.so"
              name="ignition::gazebo::systems::TriggeredPublisher">
          <input type="ignition.msgs.Int32" topic="/keyboard/keypress">
              <match field="data">87</match>
          </input>
          <output type="ignition.msgs.Twist" topic="/cmd_vel">
              linear: {x: 0.5}, angular: {z: 0.0}
          </output>
      </plugin>

      <!-- Moving Backward: X -->
      <plugin filename="libignition-gazebo-triggered-publisher-system.so"
              name="ignition::gazebo::systems::TriggeredPublisher">
          <input type="ignition.msgs.Int32" topic="/keyboard/keypress">
              <match field="data">88</match>
          </input>
          <output type="ignition.msgs.Twist" topic="/cmd_vel">
              linear: {x: -0.5}, angular: {z: 0.0}
          </output>
      </plugin>

      <!-- Rotating right: D -->
      <plugin filename="libignition-gazebo-triggered-publisher-system.so"
              name="ignition::gazebo::systems::TriggeredPublisher">
          <input type="ignition.msgs.Int32" topic="/keyboard/keypress">
              <match field="data">68</match>
          </input>
          <output type="ignition.msgs.Twist" topic="/cmd_vel">
              linear: {x: 0.0}, angular: {z: -0.5}
          </output>
      </plugin>

      <!--Rotating left: A -->
      <plugin filename="libignition-gazebo-triggered-publisher-system.so"
              name="ignition::gazebo::systems::TriggeredPublisher">
          <input type="ignition.msgs.Int32" topic="/keyboard/keypress">
              <match field="data">65</match>
          </input>
          <output type="ignition.msgs.Twist" topic="/cmd_vel">
              linear: {x: 0.0}, angular: {z: 0.5}
          </output>
      </plugin>

      <!--Stop: S -->
      <plugin filename="libignition-gazebo-triggered-publisher-system.so"
              name="ignition::gazebo::systems::TriggeredPublisher">
          <input type="ignition.msgs.Int32" topic="/keyboard/keypress">
              <match field="data">83</match>
          </input>
          <output type="ignition.msgs.Twist" topic="/cmd_vel">
              linear: {x: 0.0}, angular: {z: 0.0}
          </output>
      </plugin>

    </model>

    <model name='slide-0'>
      <pose>-24 -21.5 13.5 -0.45 0 -0.74</pose>
      <static>1</static>
      <link name='link'>
        <pose>0 0 0.45 0 0 0</pose>
        <visual name='visual'>
          <cast_shadows>0</cast_shadows>
          <geometry>
            <box>
              <size>1.7 0.001 0.9</size>
            </box>
          </geometry>
          <material>
            <diffuse>1 1 1 1</diffuse>
            <emissive>0.5 0.5 0.5 1</emissive>
            <pbr>
              <metal>
                <albedo_map>slides/slide-0.png</albedo_map>
                <emissive_map>slides/slide-0.png</emissive_map>
              </metal>
            </pbr>
          </material>
        </visual>
      </link>
    </model>

    <model name='slide-1'>
      <pose>-24 -10 5 0 0 -1.52</pose>
      <static>1</static>
      <link name='link'>
        <pose>0 0 0.45 0 0 0</pose>
        <visual name='visual'>
          <cast_shadows>0</cast_shadows>
          <geometry>
            <box>
              <size>1.7 0.001 0.9</size>
            </box>
          </geometry>
          <material>
            <diffuse>1 1 1 1</diffuse>
            <emissive>0.5 0.5 0.5 1</emissive>
            <pbr>
              <metal>
                <albedo_map>slides/slide-1.png</albedo_map>
                <emissive_map>slides/slide-1.png</emissive_map>
              </metal>
            </pbr>
          </material>
        </visual>
      </link>
    </model>

    <model name='slide-2'>
      <pose>0 6 0 0 0 2.63</pose>
      <static>1</static>
      <link name='link'>
        <pose>0 0 0.45 0 0 0</pose>
        <visual name='visual'>
          <cast_shadows>0</cast_shadows>
          <geometry>
            <box>
              <size>1.7 0.001 0.9</size>
            </box>
          </geometry>
          <material>
            <diffuse>1 1 1 1</diffuse>
            <emissive>0.5 0.5 0.5 1</emissive>
            <pbr>
              <metal>
                <albedo_map>slides/slide-2.png</albedo_map>
                <emissive_map>slides/slide-2.png</emissive_map>
              </metal>
            </pbr>
          </material>
        </visual>
      </link>
    </model>

    <model name='slide-3'>
      <pose>0 9 0 0 0 0</pose>
      <static>1</static>
      <link name='link'>
        <pose>0 0 0.45 0 0 0</pose>
        <visual name='visual'>
          <cast_shadows>0</cast_shadows>
          <geometry>
            <box>
              <size>1.7 0.001 0.9</size>
            </box>
          </geometry>
          <material>
            <diffuse>1 1 1 1</diffuse>
            <emissive>0.5 0.5 0.5 1</emissive>
            <pbr>
              <metal>
                <albedo_map>slides/slide-3.png</albedo_map>
                <emissive_map>slides/slide-3.png</emissive_map>
              </metal>
            </pbr>
          </material>
        </visual>
      </link>
    </model>

    <model name='slide-4'>
      <pose>3 0 0 0 0 0</pose>
      <static>1</static>
      <link name='link'>
        <pose>0 0 0.45 0 0 0</pose>
        <visual name='visual'>
          <cast_shadows>0</cast_shadows>
          <geometry>
            <box>
              <size>1.7 0.001 0.9</size>
            </box>
          </geometry>
          <material>
            <diffuse>1 1 1 1</diffuse>
            <emissive>0.5 0.5 0.5 1</emissive>
            <pbr>
              <metal>
                <albedo_map>slides/slide-4.png</albedo_map>
                <emissive_map>slides/slide-4.png</emissive_map>
              </metal>
            </pbr>
          </material>
        </visual>
      </link>
    </model>

    <model name='slide-5'>
      <pose>3 0 0 0 0 0</pose>
      <static>1</static>
      <link name='link'>
        <pose>0 0 0.45 0 0 0</pose>
        <visual name='visual'>
          <cast_shadows>0</cast_shadows>
          <geometry>
            <box>
              <size>1.7 0.001 0.9</size>
            </box>
          </geometry>
          <material>
            <diffuse>1 1 1 1</diffuse>
            <emissive>0.5 0.5 0.5 1</emissive>
            <pbr>
              <metal>
                <albedo_map>slides/slide-5.png</albedo_map>
                <emissive_map>slides/slide-5.png</emissive_map>
              </metal>
            </pbr>
          </material>
        </visual>
      </link>
    </model>

    <model name='slide-6'>
      <pose>3 6 0 0 0 0</pose>
      <static>1</static>
      <link name='link'>
        <pose>0 0 0.45 0 0 0</pose>
        <visual name='visual'>
          <transparency>0.01</transparency>
          <cast_shadows>0</cast_shadows>
          <geometry>
            <box>
              <size>1.7 0.001 0.9</size>
            </box>
          </geometry>
          <material>
            <diffuse>1 1 1 1</diffuse>
            <emissive>0.5 0.5 0.5 1</emissive>
            <pbr>
              <metal>
                <albedo_map>slides/slide-6.png</albedo_map>
                <emissive_map>slides/slide-6.png</emissive_map>
              </metal>
            </pbr>
          </material>
        </visual>
      </link>
    </model>

    <model name='slide-7'>
      <pose>3 9 0 0 0 0</pose>
      <static>1</static>
      <link name='link'>
        <pose>0 0 0.45 0 0 0</pose>
        <visual name='visual'>
          <cast_shadows>0</cast_shadows>
          <geometry>
            <box>
              <size>1.7 0.001 0.9</size>
            </box>
          </geometry>
          <material>
            <diffuse>1 1 1 1</diffuse>
            <emissive>0.5 0.5 0.5 1</emissive>
            <pbr>
              <metal>
                <albedo_map>slides/slide-7.png</albedo_map>
                <emissive_map>slides/slide-7.png</emissive_map>
              </metal>
            </pbr>
          </material>
        </visual>
      </link>
    </model>

    <model name='slide-8'>
      <pose>6 0 0 0 0 0</pose>
      <static>1</static>
      <link name='link'>
        <pose>0 0 0.45 0 0 0</pose>
        <visual name='visual'>
          <cast_shadows>0</cast_shadows>
          <transparency>0.01</transparency>
          <geometry>
            <box>
              <size>1.7 0.001 0.9</size>
            </box>
          </geometry>
          <material>
            <diffuse>1 1 1 1</diffuse>
            <emissive>0.5 0.5 0.5 1</emissive>
            <pbr>
              <metal>
                <albedo_map>slides/slide-8.png</albedo_map>
                <emissive_map>slides/slide-8.png</emissive_map>
              </metal>
            </pbr>
          </material>
        </visual>
      </link>
    </model>

    <model name='slide-9'>
      <pose>6 3 0 0 0 0</pose>
      <static>1</static>
      <link name='link'>
        <pose>0 0 0.45 0 0 0</pose>
        <visual name='visual'>
          <cast_shadows>0</cast_shadows>
          <transparency>0.01</transparency>
          <geometry>
            <box>
              <size>1.7 0.001 0.9</size>
            </box>
          </geometry>
          <material>
            <diffuse>1 1 1 1</diffuse>
            <emissive>0.5 0.5 0.5 1</emissive>
            <pbr>
              <metal>
                <albedo_map>slides/slide-9.png</albedo_map>
                <emissive_map>slides/slide-9.png</emissive_map>
              </metal>
            </pbr>
          </material>
        </visual>
      </link>
    </model>

    <model name='slide-10'>
      <pose>6 6 0 0 0 0</pose>
      <static>1</static>
      <link name='link'>
        <pose>0 0 0.45 0 0 0</pose>
        <visual name='visual'>
          <cast_shadows>0</cast_shadows>
          <geometry>
            <box>
              <size>1.7 0.001 0.9</size>
            </box>
          </geometry>
          <material>
            <diffuse>1 1 1 1</diffuse>
            <emissive>0.5 0.5 0.5 1</emissive>
            <pbr>
              <metal>
                <albedo_map>slides/slide-10.png</albedo_map>
                <emissive_map>slides/slide-10.png</emissive_map>
              </metal>
            </pbr>
          </material>
        </visual>
      </link>
    </model>

    <model name='slide-11'>
      <pose>6 9 0 0 0 0</pose>
      <static>1</static>
      <link name='link'>
        <pose>0 0 0.45 0 0 0</pose>
        <visual name='visual'>
          <cast_shadows>0</cast_shadows>
          <transparency>0.01</transparency>
          <geometry>
            <box>
              <size>1.7 0.001 0.9</size>
            </box>
          </geometry>
          <material>
            <diffuse>1 1 1 1</diffuse>
            <emissive>0.5 0.5 0.5 1</emissive>
            <pbr>
              <metal>
                <albedo_map>slides/slide-11.png</albedo_map>
                <emissive_map>slides/slide-11.png</emissive_map>
              </metal>
            </pbr>
          </material>
        </visual>
      </link>
    </model>

    <model name='slide-12'>
      <pose>9 0 0 0 0 0</pose>
      <static>1</static>
      <link name='link'>
        <pose>0 0 0.45 0 0 0</pose>
        <visual name='visual'>
          <cast_shadows>0</cast_shadows>
          <geometry>
            <box>
              <size>1.7 0.001 0.9</size>
            </box>
          </geometry>
          <material>
            <diffuse>1 1 1 1</diffuse>
            <emissive>0.5 0.5 0.5 1</emissive>
            <pbr>
              <metal>
                <albedo_map>slides/slide-12.png</albedo_map>
                <emissive_map>slides/slide-12.png</emissive_map>
              </metal>
            </pbr>
          </material>
        </visual>
      </link>
    </model>

    <model name='slide-13'>
      <pose>9 3 0 0 0 0</pose>
      <static>1</static>
      <link name='link'>
        <pose>0 0 0.45 0 0 0</pose>
        <visual name='visual'>
          <cast_shadows>0</cast_shadows>
          <transparency>0.01</transparency>
          <geometry>
            <box>
              <size>1.7 0.001 0.9</size>
            </box>
          </geometry>
          <material>
            <diffuse>1 1 1 1</diffuse>
            <emissive>0.5 0.5 0.5 1</emissive>
            <pbr>
              <metal>
                <albedo_map>slides/slide-13.png</albedo_map>
                <emissive_map>slides/slide-13.png</emissive_map>
              </metal>
            </pbr>
          </material>
        </visual>
      </link>
    </model>

    <model name='slide-14'>
      <pose>9 6 0 0 0 0</pose>
      <static>1</static>
      <link name='link'>
        <pose>0 0 0.45 0 0 0</pose>
        <visual name='visual'>
          <cast_shadows>0</cast_shadows>
          <geometry>
            <box>
              <size>1.7 0.001 0.9</size>
            </box>
          </geometry>
          <material>
            <diffuse>1 1 1 1</diffuse>
            <emissive>0.5 0.5 0.5 1</emissive>
            <pbr>
              <metal>
                <albedo_map>slides/slide-14.png</albedo_map>
                <emissive_map>slides/slide-14.png</emissive_map>
              </metal>
            </pbr>
          </material>
        </visual>
      </link>
    </model>

    <model name='slide-15'>
      <pose>9 9 0 0 0 0</pose>
      <static>1</static>
      <link name='link'>
        <pose>0 0 0.45 0 0 0</pose>
        <visual name='visual'>
          <cast_shadows>0</cast_shadows>
          <transparency>0.01</transparency>
          <geometry>
            <box>
              <size>1.7 0.001 0.9</size>
            </box>
          </geometry>
          <material>
            <diffuse>1 1 1 1</diffuse>
            <emissive>0.5 0.5 0.5 1</emissive>
            <pbr>
              <metal>
                <albedo_map>slides/slide-15.png</albedo_map>
                <emissive_map>slides/slide-15.png</emissive_map>
              </metal>
            </pbr>
          </material>
        </visual>
      </link>
    </model>
  </world>
</sdf>
